<!--URDF generated by ONSHAPE BY PTC INC, 1.214-->
<robot name="assembly_1">
    <link name="copy_of_rbt_thm_connectorhousing_v1_0_for_urdf">
        <inertial>
            <mass value="7.0126e-06" />
            <origin xyz="0.00877087 0.00767907 0.0095" rpy="0 -0 0" />
            <inertia ixx="7.367e-10" ixy="-3.68244e-11" ixz="0" iyy="1.41782e-09" iyz="0" izz="1.02901e-09" />
        </inertial>
        <visual>
            <origin xyz="0.0049171 0.002 0.0095" rpy="0 -0 0" />
            <geometry>
                <mesh filename="package://assembly_1/meshes/Copy_of_RBT_THM_ConnectorHousing_V1_0_FOR_URDF.stl" scale="1 1 1" />
            </geometry>
            <material name="0.792157_0.819608_0.933333_0.000000_0.000000">
                <color rgba="0.792157 0.819608 0.933333 1" />
            </material>
        </visual>
    </link>
    <link name="copy_of_rbt_thm_proximaljoint_asm_v1_0_for_urdf">
        <inertial>
            <mass value="4.50305e-06" />
            <origin xyz="-0.0106446 0.0102161 0.00620809" rpy="0 -0 0" />
            <inertia ixx="3.38752e-10" ixy="3.67683e-11" ixz="1.05329e-11" iyy="8.99501e-10" iyz="-4.88793e-11" izz="1.01117e-09" />
        </inertial>
        <visual>
            <origin xyz="-0.00950312 0 0.00512808" rpy="0 -0 0" />
            <geometry>
                <mesh filename="package://assembly_1/meshes/Copy_of_RBT_THM_ProximalJoint_ASM_V1_0_FOR_URDF.stl" scale="1 1 1" />
            </geometry>
            <material name="0.792157_0.819608_0.933333_0.000000_0.000000">
                <color rgba="0.792157 0.819608 0.933333 1" />
            </material>
        </visual>
    </link>
    <link name="dmc_2">
        <inertial>
            <mass value="1.01558e-06" />
            <origin xyz="-0.00149884 0.00521918 0.00392866" rpy="0 -0 0" />
            <inertia ixx="2.47175e-11" ixy="-3.93063e-13" ixz="1.34755e-15" iyy="4.04825e-11" iyz="-2.64017e-12" izz="4.32497e-11" />
        </inertial>
        <visual>
            <origin xyz="-0.0015 0.0045 0" rpy="0 -0 0" />
            <geometry>
                <mesh filename="package://assembly_1/meshes/DMC_2.stl" scale="1 1 1" />
            </geometry>
            <material name="0.792157_0.819608_0.933333_0.000000_0.000000">
                <color rgba="0.792157 0.819608 0.933333 1" />
            </material>
        </visual>
    </link>
    <link name="dmc_2_1">
        <inertial>
            <mass value="1.01558e-06" />
            <origin xyz="-0.00149884 0.00521918 0.00392866" rpy="0 -0 0" />
            <inertia ixx="2.47175e-11" ixy="-3.93063e-13" ixz="1.34755e-15" iyy="4.04825e-11" iyz="-2.64017e-12" izz="4.32497e-11" />
        </inertial>
        <visual>
            <origin xyz="-0.0015 0.0045 0" rpy="0 -0 0" />
            <geometry>
                <mesh filename="package://assembly_1/meshes/DMC_2.stl" scale="1 1 1" />
            </geometry>
            <material name="0.792157_0.819608_0.933333_0.000000_0.000000">
                <color rgba="0.792157 0.819608 0.933333 1" />
            </material>
        </visual>
    </link>
    <link name="dmc_2_2">
        <inertial>
            <mass value="1.01558e-06" />
            <origin xyz="-0.00149884 0.00521918 0.00392866" rpy="0 -0 0" />
            <inertia ixx="2.47175e-11" ixy="-3.93063e-13" ixz="1.34755e-15" iyy="4.04825e-11" iyz="-2.64017e-12" izz="4.32497e-11" />
        </inertial>
        <visual>
            <origin xyz="-0.0015 0.0045 0" rpy="0 -0 0" />
            <geometry>
                <mesh filename="package://assembly_1/meshes/DMC_2.stl" scale="1 1 1" />
            </geometry>
            <material name="0.792157_0.819608_0.933333_0.000000_0.000000">
                <color rgba="0.792157 0.819608 0.933333 1" />
            </material>
        </visual>
    </link>
    <link name="dmc_2_3">
        <inertial>
            <mass value="1.01558e-06" />
            <origin xyz="-0.00149884 0.00521918 0.00392866" rpy="0 -0 0" />
            <inertia ixx="2.47175e-11" ixy="-3.93063e-13" ixz="1.34755e-15" iyy="4.04825e-11" iyz="-2.64017e-12" izz="4.32497e-11" />
        </inertial>
        <visual>
            <origin xyz="-0.0015 0.0045 0" rpy="0 -0 0" />
            <geometry>
                <mesh filename="package://assembly_1/meshes/DMC_2.stl" scale="1 1 1" />
            </geometry>
            <material name="0.792157_0.819608_0.933333_0.000000_0.000000">
                <color rgba="0.792157 0.819608 0.933333 1" />
            </material>
        </visual>
    </link>
    <link name="dp_10_3">
        <inertial>
            <mass value="7.01317e-06" />
            <origin xyz="-0.00495459 0.0185223 1.79992e-05" rpy="0 -0 0" />
            <inertia ixx="7.09132e-10" ixy="8.15569e-14" ixz="1.02214e-13" iyy="2.62196e-10" iyz="-5.94733e-12" izz="7.21098e-10" />
        </inertial>
        <visual>
            <origin xyz="-0.00495 -0.0045 -0.0012" rpy="0 -0 0" />
            <geometry>
                <mesh filename="package://assembly_1/meshes/DP_10_3.stl" scale="1 1 1" />
            </geometry>
            <material name="0.792157_0.819608_0.933333_0.000000_0.000000">
                <color rgba="0.792157 0.819608 0.933333 1" />
            </material>
        </visual>
    </link>
    <link name="dp_10_3_1">
        <inertial>
            <mass value="7.01317e-06" />
            <origin xyz="-0.00495459 0.0185223 1.79992e-05" rpy="0 -0 0" />
            <inertia ixx="7.09132e-10" ixy="8.15569e-14" ixz="1.02214e-13" iyy="2.62196e-10" iyz="-5.94733e-12" izz="7.21098e-10" />
        </inertial>
        <visual>
            <origin xyz="-0.00495 -0.0045 -0.0012" rpy="0 -0 0" />
            <geometry>
                <mesh filename="package://assembly_1/meshes/DP_10_3.stl" scale="1 1 1" />
            </geometry>
            <material name="0.792157_0.819608_0.933333_0.000000_0.000000">
                <color rgba="0.792157 0.819608 0.933333 1" />
            </material>
        </visual>
    </link>
    <link name="dp_10_3_2">
        <inertial>
            <mass value="7.01317e-06" />
            <origin xyz="-0.00495459 0.0185223 1.79992e-05" rpy="0 -0 0" />
            <inertia ixx="7.09132e-10" ixy="8.15569e-14" ixz="1.02214e-13" iyy="2.62196e-10" iyz="-5.94733e-12" izz="7.21098e-10" />
        </inertial>
        <visual>
            <origin xyz="-0.00495 -0.0045 -0.0012" rpy="0 -0 0" />
            <geometry>
                <mesh filename="package://assembly_1/meshes/DP_10_3.stl" scale="1 1 1" />
            </geometry>
            <material name="0.792157_0.819608_0.933333_0.000000_0.000000">
                <color rgba="0.792157 0.819608 0.933333 1" />
            </material>
        </visual>
    </link>
    <link name="dp_10_3_3">
        <inertial>
            <mass value="7.01317e-06" />
            <origin xyz="-0.00495459 0.0185223 1.79992e-05" rpy="0 -0 0" />
            <inertia ixx="7.09132e-10" ixy="8.15569e-14" ixz="1.02214e-13" iyy="2.62196e-10" iyz="-5.94733e-12" izz="7.21098e-10" />
        </inertial>
        <visual>
            <origin xyz="-0.00495 -0.0045 -0.0012" rpy="0 -0 0" />
            <geometry>
                <mesh filename="package://assembly_1/meshes/DP_10_3.stl" scale="1 1 1" />
            </geometry>
            <material name="0.792157_0.819608_0.933333_0.000000_0.000000">
                <color rgba="0.792157 0.819608 0.933333 1" />
            </material>
        </visual>
    </link>
    <link name="mcp_10_1">
        <inertial>
            <mass value="7.62893e-06" />
            <origin xyz="-0.00489163 0.021268 0.00322575" rpy="0 -0 0" />
            <inertia ixx="9.77276e-10" ixy="-1.36354e-12" ixz="4.80569e-13" iyy="3.02506e-10" iyz="-6.428e-12" izz="1.0097e-09" />
        </inertial>
        <visual>
            <origin xyz="-0.0049 -0.0035 0.0022" rpy="0 -0 0" />
            <geometry>
                <mesh filename="package://assembly_1/meshes/MCP_10_1.stl" scale="1 1 1" />
            </geometry>
            <material name="0.792157_0.819608_0.933333_0.000000_0.000000">
                <color rgba="0.792157 0.819608 0.933333 1" />
            </material>
        </visual>
    </link>
    <link name="mcp_10_1_1">
        <inertial>
            <mass value="7.62893e-06" />
            <origin xyz="-0.00489163 0.021268 0.00322575" rpy="0 -0 0" />
            <inertia ixx="9.77276e-10" ixy="-1.36354e-12" ixz="4.80569e-13" iyy="3.02506e-10" iyz="-6.428e-12" izz="1.0097e-09" />
        </inertial>
        <visual>
            <origin xyz="-0.0049 -0.0035 0.0022" rpy="0 -0 0" />
            <geometry>
                <mesh filename="package://assembly_1/meshes/MCP_10_1.stl" scale="1 1 1" />
            </geometry>
            <material name="0.792157_0.819608_0.933333_0.000000_0.000000">
                <color rgba="0.792157 0.819608 0.933333 1" />
            </material>
        </visual>
    </link>
    <link name="mcp_10_1_2">
        <inertial>
            <mass value="7.62893e-06" />
            <origin xyz="-0.00489163 0.021268 0.00322575" rpy="0 -0 0" />
            <inertia ixx="9.77276e-10" ixy="-1.36354e-12" ixz="4.80569e-13" iyy="3.02506e-10" iyz="-6.428e-12" izz="1.0097e-09" />
        </inertial>
        <visual>
            <origin xyz="-0.0049 -0.0035 0.0022" rpy="0 -0 0" />
            <geometry>
                <mesh filename="package://assembly_1/meshes/MCP_10_1.stl" scale="1 1 1" />
            </geometry>
            <material name="0.792157_0.819608_0.933333_0.000000_0.000000">
                <color rgba="0.792157 0.819608 0.933333 1" />
            </material>
        </visual>
    </link>
    <link name="mcp_10_1_3">
        <inertial>
            <mass value="7.62893e-06" />
            <origin xyz="-0.00489163 0.021268 0.00322575" rpy="0 -0 0" />
            <inertia ixx="9.77276e-10" ixy="-1.36354e-12" ixz="4.80569e-13" iyy="3.02506e-10" iyz="-6.428e-12" izz="1.0097e-09" />
        </inertial>
        <visual>
            <origin xyz="-0.0049 -0.0035 0.0022" rpy="0 -0 0" />
            <geometry>
                <mesh filename="package://assembly_1/meshes/MCP_10_1.stl" scale="1 1 1" />
            </geometry>
            <material name="0.792157_0.819608_0.933333_0.000000_0.000000">
                <color rgba="0.792157 0.819608 0.933333 1" />
            </material>
        </visual>
    </link>
    <link name="palm_3">
        <inertial>
            <mass value="5.55353e-05" />
            <origin xyz="0.00367064 0.00262538 0.00420244" rpy="0 -0 0" />
            <inertia ixx="7.01154e-08" ixy="-3.73709e-10" ixz="-7.47787e-10" iyy="4.5229e-08" iyz="1.74576e-09" izz="1.13323e-07" />
        </inertial>
        <visual>
            <origin xyz="0 0 0" rpy="0 -0 0" />
            <geometry>
                <mesh filename="package://assembly_1/meshes/PALM_3.stl" scale="1 1 1" />
            </geometry>
            <material name="0.792157_0.819608_0.933333_0.000000_0.000000">
                <color rgba="0.792157 0.819608 0.933333 1" />
            </material>
        </visual>
    </link>
    <link name="palm_front_case">
        <inertial>
            <mass value="5.17623e-05" />
            <origin xyz="-0.0292414 -0.0502367 0.00642036" rpy="0 -0 0" />
            <inertia ixx="3.67375e-08" ixy="5.90872e-09" ixz="2.3393e-10" iyy="4.32587e-08" iyz="-1.34415e-10" izz="7.91984e-08" />
        </inertial>
        <visual>
            <origin xyz="-0.0415045 -0.0666293 0" rpy="0 -0 0" />
            <geometry>
                <mesh filename="package://assembly_1/meshes/PALM_FRONT_CASE.stl" scale="1 1 1" />
            </geometry>
            <material name="0.792157_0.819608_0.933333_0.000000_0.000000">
                <color rgba="0.792157 0.819608 0.933333 1" />
            </material>
        </visual>
    </link>
    <link name="pip_10_2">
        <inertial>
            <mass value="5.31371e-06" />
            <origin xyz="-0.00491635 0.0160516 5.63426e-05" rpy="0 -0 0" />
            <inertia ixx="4.13066e-10" ixy="-6.52751e-13" ixz="3.2996e-13" iyy="2.20585e-10" iyz="1.02892e-12" izz="4.39131e-10" />
        </inertial>
        <visual>
            <origin xyz="-0.00495 -0.0043 -0.001" rpy="0 -0 0" />
            <geometry>
                <mesh filename="package://assembly_1/meshes/PIP_10_2.stl" scale="1 1 1" />
            </geometry>
            <material name="0.792157_0.819608_0.933333_0.000000_0.000000">
                <color rgba="0.792157 0.819608 0.933333 1" />
            </material>
        </visual>
    </link>
    <link name="pip_10_2_1">
        <inertial>
            <mass value="5.31371e-06" />
            <origin xyz="-0.00491635 0.0160516 5.63426e-05" rpy="0 -0 0" />
            <inertia ixx="4.13066e-10" ixy="-6.52751e-13" ixz="3.2996e-13" iyy="2.20585e-10" iyz="1.02892e-12" izz="4.39131e-10" />
        </inertial>
        <visual>
            <origin xyz="-0.00495 -0.0043 -0.001" rpy="0 -0 0" />
            <geometry>
                <mesh filename="package://assembly_1/meshes/PIP_10_2.stl" scale="1 1 1" />
            </geometry>
            <material name="0.792157_0.819608_0.933333_0.000000_0.000000">
                <color rgba="0.792157 0.819608 0.933333 1" />
            </material>
        </visual>
    </link>
    <link name="pip_10_2_2">
        <inertial>
            <mass value="5.31371e-06" />
            <origin xyz="-0.00491635 0.0160516 5.63426e-05" rpy="0 -0 0" />
            <inertia ixx="4.13066e-10" ixy="-6.52751e-13" ixz="3.2996e-13" iyy="2.20585e-10" iyz="1.02892e-12" izz="4.39131e-10" />
        </inertial>
        <visual>
            <origin xyz="-0.00495 -0.0043 -0.001" rpy="0 -0 0" />
            <geometry>
                <mesh filename="package://assembly_1/meshes/PIP_10_2.stl" scale="1 1 1" />
            </geometry>
            <material name="0.792157_0.819608_0.933333_0.000000_0.000000">
                <color rgba="0.792157 0.819608 0.933333 1" />
            </material>
        </visual>
    </link>
    <link name="pip_10_2_3">
        <inertial>
            <mass value="5.31371e-06" />
            <origin xyz="-0.00491635 0.0160516 5.63426e-05" rpy="0 -0 0" />
            <inertia ixx="4.13066e-10" ixy="-6.52751e-13" ixz="3.2996e-13" iyy="2.20585e-10" iyz="1.02892e-12" izz="4.39131e-10" />
        </inertial>
        <visual>
            <origin xyz="-0.00495 -0.0043 -0.001" rpy="0 -0 0" />
            <geometry>
                <mesh filename="package://assembly_1/meshes/PIP_10_2.stl" scale="1 1 1" />
            </geometry>
            <material name="0.792157_0.819608_0.933333_0.000000_0.000000">
                <color rgba="0.792157 0.819608 0.933333 1" />
            </material>
        </visual>
    </link>
    <link name="root" />
    <link name="thumb__test__1_1">
        <inertial>
            <mass value="3.53441e-06" />
            <origin xyz="-0.00885072 0.0115332 0.000495545" rpy="0 -0 0" />
            <inertia ixx="3.0275e-10" ixy="-3.7518e-12" ixz="2.61454e-13" iyy="2.62352e-10" iyz="7.3534e-12" izz="2.66199e-10" />
        </inertial>
        <visual>
            <origin xyz="-0.009 -0.003 0" rpy="0 -0 0" />
            <geometry>
                <mesh filename="package://assembly_1/meshes/thumb__test__1_1.stl" scale="1 1 1" />
            </geometry>
            <material name="0.792157_0.819608_0.933333_0.000000_0.000000">
                <color rgba="0.792157 0.819608 0.933333 1" />
            </material>
        </visual>
    </link>
    <link name="thumb_dp_2_1">
        <inertial>
            <mass value="8.15417e-06" />
            <origin xyz="0.00699789 0.0210996 0.00201128" rpy="0 -0 0" />
            <inertia ixx="1.17763e-09" ixy="-1.73832e-13" ixz="-6.9032e-14" iyy="3.22121e-10" iyz="1.17996e-11" izz="1.1384e-09" />
        </inertial>
        <visual>
            <origin xyz="0.007 0.006 0.002" rpy="0 -0 0" />
            <geometry>
                <mesh filename="package://assembly_1/meshes/THUMB_DP_2_1.stl" scale="1 1 1" />
            </geometry>
            <material name="0.792157_0.819608_0.933333_0.000000_0.000000">
                <color rgba="0.792157 0.819608 0.933333 1" />
            </material>
        </visual>
    </link>
    <link name="thumb_mcp_2_1">
        <inertial>
            <mass value="1.20028e-05" />
            <origin xyz="-0.0100008 0.0338656 0.0168232" rpy="0 -0 0" />
            <inertia ixx="3.52153e-09" ixy="1.47351e-13" ixz="3.27677e-14" iyy="1.1646e-09" iyz="-2.84397e-10" izz="3.59907e-09" />
        </inertial>
        <visual>
            <origin xyz="0.0352796 0.0525 0.0295236" rpy="0 -0 0" />
            <geometry>
                <mesh filename="package://assembly_1/meshes/THUMB_MCP_2_1.stl" scale="1 1 1" />
            </geometry>
            <material name="0.792157_0.819608_0.933333_0.000000_0.000000">
                <color rgba="0.792157 0.819608 0.933333 1" />
            </material>
        </visual>
    </link>
    <joint name="fastened_1_0" type="fixed">
        <origin xyz="-0.0106734 -0.0158818 0.004" rpy="1.5708 -0 0" />
        <axis xyz="0 1 0" />
        <parent link="palm_3" />
        <child link="copy_of_rbt_thm_connectorhousing_v1_0_for_urdf" />
    </joint>
    <joint name="fastened_2_0" type="fixed">
        <origin xyz="-0.0125 0.00747372 0" rpy="0 1.5708 1.0472" />
        <axis xyz="0 -1 0" />
        <parent link="copy_of_rbt_thm_connectorhousing_v1_0_for_urdf" />
        <child link="copy_of_rbt_thm_proximaljoint_asm_v1_0_for_urdf" />
    </joint>
    <joint name="fastened_3_0" type="fixed">
        <origin xyz="0.00884603 0.0516182 0.004" rpy="0 -0 0" />
        <axis xyz="0 0 1" />
        <parent link="palm_3" />
        <child link="dmc_2_3" />
    </joint>
    <joint name="fastened_4_0" type="fixed">
        <origin xyz="0.026846 0.0516182 0.004" rpy="0 -0 0" />
        <axis xyz="0 0 -1" />
        <parent link="palm_3" />
        <child link="dmc_2" />
    </joint>
    <joint name="fastened_5_0" type="fixed">
        <origin xyz="-0.00915397 0.0516182 0.004" rpy="0 -0 0" />
        <axis xyz="0 0 -1" />
        <parent link="palm_3" />
        <child link="dmc_2_2" />
    </joint>
    <joint name="fastened_6_0" type="fixed">
        <origin xyz="-0.027154 0.0516182 0.004" rpy="0 -0 0" />
        <axis xyz="0 0 -1" />
        <parent link="palm_3" />
        <child link="dmc_2_1" />
    </joint>
    <joint name="fastened_7_0" type="fixed">
        <origin xyz="0.0387616 0.0601588 0.017" rpy="0 -0 0" />
        <axis xyz="0 0 -1" />
        <parent link="palm_3" />
        <child link="palm_front_case" />
    </joint>
    <joint name="fixed_node_to_root_joint_0" type="fixed">
        <origin xyz="-0.0168893 -0.00788492 8.97363e-06" rpy="0 -0 0" />
        <axis xyz="0 0 1" />
        <parent link="root" />
        <child link="palm_3" />
    </joint>
    <joint name="index_dip_0" type="continuous">
        <origin xyz="0.0001 0.0312 2.28983e-16" rpy="-0.00589183 1.54812e-21 -8.68144e-17" />
        <axis xyz="1 0 0" />
        <parent link="pip_10_2" />
        <child link="dp_10_3_1" />
    </joint>
    <joint name="index_mcp_0" type="continuous">
        <origin xyz="0.0035 0.008 0.01" rpy="-2.6484e-15 -1.50387e-36 3.85799e-34" />
        <axis xyz="-1 0 0" />
        <parent link="dmc_2_1" />
        <child link="mcp_10_1_2" />
    </joint>
    <joint name="index_pip_0" type="continuous">
        <origin xyz="0.00015 0.042 0.0032" rpy="-0.0183108 -3.0578e-18 8.67215e-17" />
        <axis xyz="-1 0 0" />
        <parent link="mcp_10_1_2" />
        <child link="pip_10_2" />
    </joint>
    <joint name="little_dip_0" type="continuous">
        <origin xyz="0.0001 0.0312 1.5439e-16" rpy="0.0227389 -2.22903e-25 -8.67362e-17" />
        <axis xyz="1 0 0" />
        <parent link="pip_10_2_1" />
        <child link="dp_10_3" />
    </joint>
    <joint name="little_mcp_0" type="continuous">
        <origin xyz="0.0035 0.008 0.01" rpy="1.79015e-16 4.69345e-17 7.08777e-17" />
        <axis xyz="-1 0 0" />
        <parent link="dmc_2" />
        <child link="mcp_10_1_1" />
    </joint>
    <joint name="little_pip_0" type="continuous">
        <origin xyz="0.00015 0.042 0.0032" rpy="0.0175213 -4.69349e-17 1.58578e-17" />
        <axis xyz="1 0 0" />
        <parent link="mcp_10_1_1" />
        <child link="pip_10_2_1" />
    </joint>
    <joint name="middle_dip_0" type="continuous">
        <origin xyz="0.0001 0.0312 0" rpy="3.20732e-48 -5.47382e-48 -8.67362e-17" />
        <axis xyz="1 0 0" />
        <parent link="pip_10_2_2" />
        <child link="dp_10_3_3" />
    </joint>
    <joint name="middle_mcp_0" type="continuous">
        <origin xyz="0.0035 0.008 0.01" rpy="0 -0 0" />
        <axis xyz="1 0 0" />
        <parent link="dmc_2_2" />
        <child link="mcp_10_1_3" />
    </joint>
    <joint name="middle_pip_0" type="continuous">
        <origin xyz="0.00015 0.042 0.0032" rpy="0 -0 8.67362e-17" />
        <axis xyz="-1 0 0" />
        <parent link="mcp_10_1_3" />
        <child link="pip_10_2_2" />
    </joint>
    <joint name="ring_dip_0" type="continuous">
        <origin xyz="0.0001 0.0312 0" rpy="-4.67853e-33 -2.46519e-32 -8.67362e-17" />
        <axis xyz="-1 0 0" />
        <parent link="pip_10_2_3" />
        <child link="dp_10_3_2" />
    </joint>
    <joint name="ring_mcp_0" type="continuous">
        <origin xyz="0.0035 0.008 0.01" rpy="0 -0 0" />
        <axis xyz="-1 0 0" />
        <parent link="dmc_2_3" />
        <child link="mcp_10_1" />
    </joint>
    <joint name="ring_pip_0" type="continuous">
        <origin xyz="0.00015 0.042 0.0032" rpy="-4.00915e-49 -9.24446e-33 8.67362e-17" />
        <axis xyz="1 0 0" />
        <parent link="mcp_10_1" />
        <child link="pip_10_2_3" />
    </joint>
    <joint name="thumb_dmc_0" type="continuous">
        <origin xyz="0.00199688 0.017371 0.00825761" rpy="-0.523599 6.20996e-17 -2.81856e-17" />
        <axis xyz="1 0 0" />
        <parent link="copy_of_rbt_thm_proximaljoint_asm_v1_0_for_urdf" />
        <child link="thumb__test__1_1" />
    </joint>
    <joint name="thumb_ip_0" type="continuous">
        <origin xyz="-0.003 0.0605 0.018" rpy="-3.14159 -9.76209e-16 -3.14159" />
        <axis xyz="-1 0 0" />
        <parent link="thumb_mcp_2_1" />
        <child link="thumb_dp_2_1" />
    </joint>
    <joint name="thumb_mcp_0" type="continuous">
        <origin xyz="-0.00895747 0.024 0.007" rpy="0 -1.5708 -0.075149" />
        <axis xyz="-1 0 0" />
        <parent link="thumb__test__1_1" />
        <child link="thumb_mcp_2_1" />
    </joint>
</robot>
